<?xml version='1.0'?>

<robot name="myrobot" xmlns:xacro="http://www.ros.org/wiki/xacro">

  <xacro:property name="cameraSize" value="0.05"/>
  <xacro:property name="cameraMass" value="0.1"/>

  <xacro:include filename="$(find mybot_description)/urdf/mybot.gazebo" />
  <xacro:include filename="$(find mybot_description)/urdf/materials.xacro" />
  <xacro:include filename="$(find mybot_description)/urdf/macros.xacro" />


  <link name='chassis'>
    <pose>0 0 0.1 0 0 0</pose>
    <collision name='collision'>
      <geometry>
        <box size=".4 .2 .1"/>
      </geometry>
    </collision>

    <visual name='chassis_visual'>
      <origin xyz="0 0 0" rpy=" 0 0 0"/>
      <geometry>
        <box size=".4 .2 .1"/>
      </geometry>
    </visual>
  </link>

<!-- added base_link to remove inertial from chassis link as this is not possible to run-->
 <link name='base_link'>
    <pose>0 0 0.0 0 0 0</pose>
    <inertial>
      <mass value="15.0"/>
      <origin xyz="0.0 0 0.0" rpy=" 0 0 0"/>
      <inertia
          ixx="0.1" ixy="0" ixz="0"
          iyy="0.1" iyz="0"
          izz="0.1"
      />
    </inertial>
    <collision name='collision'>
      <geometry>
        <box size=".4 .2 .1"/>
      </geometry>
    </collision>

    <visual name='base_link_visual'>
      <origin xyz="0 0.0 0" rpy=" 0 0 0"/>
      <geometry>
        <box size=".4 .2 .1"/>
      </geometry>
    </visual>
  </link>
  <joint name="base_chassis_joint" type="fixed">
    <axis xyz="0 0 0" />
    <origin xyz="0.0 0 0.0" rpy="0 0 0"/>
    <parent link="chassis"/>
    <child link="base_link"/>
  </joint>

  <link name="axel">
    <collision name="collision">
      <origin xyz="0.0 0 0.0" rpy="0 1.5707 1.5707"/>
      <geometry>
        <cylinder radius="0.007" length="0.25"/>
      </geometry>
    </collision>
    <visual name="axel_visual">
      <origin xyz="0.0 0.0 0.0" rpy="0 1.5707 1.5707"/>
      <geometry>
        <cylinder radius="0.007" length="0.25"/>
      </geometry>
    </visual>
    <inertial>
      <origin xyz="0.0 0 0.0" rpy="0 0 0"/>
      <mass value="5"/>
      <inertia
        ixx=".1" ixy="0.0" ixz="0.0"
        iyy=".1" iyz="0.0"
        izz=".1"/>
    </inertial>
  </link>
  <joint name="axel_joint" type="fixed">
    <axis xyz="0 1 0" />
    <origin xyz="0.15 0 -0.03" rpy="0 0 0"/>
    <parent link="chassis"/>
    <child link="axel"/>
  </joint>


  <link name="axel_hinge_left">
    <collision name="axel_hinge_collision_left">
      <origin xyz="0.0 0 0.0" rpy="0 0 0"/>
      <geometry>
        <sphere radius="0.007"/>
      </geometry>
    </collision>
    <visual name="axel_hinge_left_visual">
      <origin xyz="0.0 0.0 0.0" rpy="0 0 0"/>
      <geometry>
        <sphere radius="0.007"/>
      </geometry>
    </visual>
    <inertial>
      <origin xyz="0.0 0 0.0" rpy="0 0 0"/>
      <mass value="0.1"/>
      <inertia
        ixx=".1" ixy="0.0" ixz="0.0"
        iyy=".1" iyz="0.0"
        izz=".1"/>
    </inertial>
  </link>
  <joint name="axel_hinge_left_joint" type="revolute">
    <axis xyz="0 0 1" />
    <origin xyz="0 0.125 0" rpy="0 0 0"/>
    <parent link="axel"/>
    <child link="axel_hinge_left"/>
    <limit effort="100" velocity="10" lower="-0.2" upper="0.2"/>
    <safety_controller k_position="10" k_velocity="10" soft_lower_limit="-2" oft_upper_limitt="2"/>
    <joint_properties damping="0.1" friction="0.0"/>
  </joint>


  <link name="axel_hinge_right">
    <collision name="axel_hinge_collision_right">
      <origin xyz="0.0 0 0.0" rpy="0 0 0"/>
      <geometry>
        <sphere radius="0.007"/>
      </geometry>
    </collision>
    <visual name="axel_hinge_right_visual">
      <origin xyz="0.0 0.0 0.0" rpy="0 0 0"/>
      <geometry>
        <sphere radius="0.007"/>
      </geometry>
    </visual>
    <inertial>
      <origin xyz="0.0 0 0.0" rpy="0 0 0"/>
      <mass value="0.1"/>
      <inertia
        ixx=".1" ixy="0.0" ixz="0.0"
        iyy=".1" iyz="0.0"
        izz=".1"/>
    </inertial>
  </link>
  <joint name="axel_hinge_right_joint" type="revolute">
    <axis xyz="0 0 1" />
    <origin xyz="0 -0.125 0" rpy="0 0 0"/>
    <parent link="axel"/>
    <child link="axel_hinge_right"/>
    <limit effort="100" velocity="10"  lower="-0.2" upper="0.2"/>
    <safety_controller k_position="10" k_velocity="10" soft_lower_limit="-0.19" oft_upper_limitt="0.19"/>
    <joint_properties damping="0.0" friction="0.0"/>
  </joint>


  <link name="left_wheel_front">
    <collision name="collision">
      <origin xyz="0.0 0 0.0" rpy="0 0 0"/>
      <geometry>
        <cylinder radius="0.08" length="0.05"/>
      </geometry>
    </collision>
    <visual name="left_wheel_front_visual">
      <origin xyz="0.0 0.0 0.0" rpy="0 1.5707 1.5707"/>
      <geometry>
        <cylinder radius="0.08" length="0.05"/>
      </geometry>
    </visual>
    <inertial>
      <origin xyz="0.0 0 -0.0" rpy="0 0 0"/>
      <mass value="0.1"/>
      <inertia
        ixx=".1" ixy="0.0" ixz="0.0"
        iyy=".1" iyz="0.0"
        izz=".1"/>
    </inertial>
  </link>
  <joint type="continuous" name="left_wheel_front_hinge">
    <origin xyz="0.0 0.025 0.00" rpy="0 0 0"/>
    <child link="left_wheel_front"/>
    <parent link="axel_hinge_left"/>
    <axis xyz="0 1 0" rpy="0 0 0"/>
    <limit effort="100" velocity="100"/>
    <joint_properties damping="1.0" friction="1.0"/>
  </joint>


  <link name="right_wheel_front">
    <collision name="collision">
      <origin xyz="0.0 0 0.0" rpy="0 1.5707 1.5707"/>
      <geometry>
        <cylinder radius="0.08" length="0.05"/>
      </geometry>
    </collision>
    <visual name="right_wheel_front_visual">
      <origin xyz="0.0 0 0.0" rpy="0 1.5707 1.5707"/>
      <geometry>
        <cylinder radius="0.08" length="0.05"/>
      </geometry>
    </visual>
    <inertial>
      <origin xyz="0.0 0 0.0" rpy="0 0 0"/>
      <mass value="0.1"/>
      <inertia
        ixx=".1" ixy="0.0" ixz="0.0"
        iyy=".1" iyz="0.0"
        izz=".1"/>
    </inertial>
  </link>
  <joint type="continuous" name="right_wheel_front_hinge">
    <origin xyz="0.0 -0.025 0.00" rpy="0 0 0"/>
    <child link="right_wheel_front"/>
    <parent link="axel_hinge_right"/>
    <axis xyz="0 1 0" rpy="0 0 0"/>
    <limit effort="100" velocity="100"/>
    <joint_properties damping="1.0" friction="1.0"/>
  </joint>


  <link name="left_wheel_back">
    <collision name="collision">
      <origin xyz="0.0 0 0.0" rpy="0 0 0"/>
      <geometry>
        <cylinder radius="0.08" length="0.05"/>
      </geometry>
    </collision>
    <visual name="left_wheel_back_visual">
      <origin xyz="0.0 0.0 0.0" rpy="0 1.5707 1.5707"/>
      <geometry>
        <cylinder radius="0.08" length="0.05"/>
      </geometry>
    </visual>
    <inertial>
      <origin xyz="0.0 0 -0.0" rpy="0 0 0"/>
      <mass value="0.01"/>
      <inertia
        ixx=".1" ixy="0.0" ixz="0.0"
        iyy=".1" iyz="0.0"
        izz=".1"/>
    </inertial>
  </link>
  <joint type="continuous" name="left_wheel_back_joint">
    <origin xyz="-0.12 0.15 -0.03" rpy="0 0 0"/>
    <child link="left_wheel_back"/>
    <parent link="base_link"/>
    <axis xyz="0 1 0" rpy="0 0 0"/>
    <dynamics damping = "0.7" />
  </joint>



  <link name="right_wheel_back">
    <collision name="collision">
      <origin xyz="0.0 0 0.0" rpy="0 1.5707 1.5707"/>
      <geometry>
        <cylinder radius="0.08" length="0.05"/>
      </geometry>
    </collision>
    <visual name="right_wheel_back_visual">
      <origin xyz="0.0 0 0.0" rpy="0 1.5707 1.5707"/>
      <geometry>
        <cylinder radius="0.08" length="0.05"/>
      </geometry>
    </visual>
    <inertial>
      <origin xyz="0.0 0 0.0" rpy="0 0 0"/>
      <mass value="0.01"/>
      <inertia
        ixx=".1" ixy="0.0" ixz="0.0"
        iyy=".1" iyz="0.0"
        izz=".1"/>
    </inertial>
  </link>
  <joint type="continuous" name="right_wheel_back_joint">
    <origin xyz="-0.12 -0.15 -0.03" rpy="0 0 0"/>
    <child link="right_wheel_back"/>
    <parent link="base_link"/>
    <axis xyz="0 1 0" rpy="0 0 0"/>
    <dynamics damping = "0.7" />
  </joint>



  <link name="camera">
    <collision>
      <origin xyz="0 0 0" rpy="0 0 0"/>
      <geometry>
        <box size="${cameraSize} ${cameraSize} ${cameraSize}"/>
      </geometry>
    </collision>

    <visual>
      <origin xyz="0 0 0" rpy="0 0 0"/>
      <geometry>
        <box size="${cameraSize} ${cameraSize} ${cameraSize}"/>
      </geometry>
      <material name="green"/>
    </visual>

    <inertial>
      <mass value="${cameraMass}" />
      <origin xyz="0 0 0" rpy="0 0 0"/>
      <box_inertia m="${cameraMass}" x="${cameraSize}" y="${cameraSize}" z="${cameraSize}" />
      <inertia ixx="1e-6" ixy="0" ixz="0" iyy="1e-6" iyz="0" izz="1e-6" />
    </inertial>
  </link>

  <joint name="camera_joint" type="fixed">
    <axis xyz="0 1 0" />
    <origin xyz=".2 0 0" rpy="0 0 0"/>
    <parent link="chassis"/>
    <child link="camera"/>
  </joint>


  <joint name="hokuyo_joint" type="fixed">
    <axis xyz="0 1 0" />
    <origin xyz=".15 0 .1" rpy="0 0 0"/>
    <parent link="chassis"/>
    <child link="hokuyo"/>
  </joint>

  <!-- Hokuyo Laser -->
  <link name="hokuyo">
    <collision>
      <origin xyz="0 0 0" rpy="0 0 0"/>
      <geometry>
    <box size="0.1 0.1 0.1"/>
      </geometry>
    </collision>

    <visual>
      <origin xyz="0 0 0" rpy="0 0 0"/>
      <geometry>
        <mesh filename="package://mybot_description/meshes/hokuyo.dae"/>
      </geometry>
    </visual>

    <inertial>
      <mass value="1e-5" />
      <origin xyz="0 0 0" rpy="0 0 0"/>
      <inertia ixx="1e-6" ixy="0" ixz="0" iyy="1e-6" iyz="0" izz="1e-6" />
    </inertial>
  </link>


  <transmission name="tran1">
    <type>transmission_interface/SimpleTransmission</type>
    <joint name="left_wheel_back_joint">
      <hardwareInterface>hardware_interface/EffortJointInterface</hardwareInterface>
    </joint>
    <actuator name="motor1">
      <hardwareInterface>hardware_interface/EffortJointInterface</hardwareInterface>
      <mechanicalReduction>1</mechanicalReduction>
    </actuator>
  </transmission>

  <transmission name="tran2">
    <type>transmission_interface/SimpleTransmission</type>
    <joint name="right_wheel_back_joint">
      <hardwareInterface>hardware_interface/EffortJointInterface</hardwareInterface>
    </joint>
    <actuator name="motor2">
      <hardwareInterface>hardware_interface/EffortJointInterface</hardwareInterface>
      <mechanicalReduction>1</mechanicalReduction>
    </actuator>
  </transmission>

  <transmission name="tran3">
    <type>transmission_interface/SimpleTransmission</type>
    <joint name="axel_hinge_right_joint">
      <hardwareInterface>hardware_interface/EffortJointInterface</hardwareInterface>
    </joint>
    <actuator name="motor3">
      <hardwareInterface>hardware_interface/EffortJointInterface</hardwareInterface>
      <mechanicalReduction>1</mechanicalReduction>
    </actuator>
  </transmission>

  <transmission name="tran4">
    <type>transmission_interface/SimpleTransmission</type>
    <joint name="axel_hinge_left_joint">
      <hardwareInterface>hardware_interface/EffortJointInterface</hardwareInterface>
    </joint>
    <actuator name="motor4">
      <hardwareInterface>hardware_interface/EffortJointInterface</hardwareInterface>
      <mechanicalReduction>1</mechanicalReduction>
    </actuator>
  </transmission>

</robot>

